Workbook
Name DeliveryDays: Overall!$B$5
Name WorkingDaysPerMonth: Overall!$B$6
Name DeliveryMonths: Overall!$B$7
Name HoursPerMonth: Overall!$B$8
Name ProjectStart: Overall!$B$9
Name SprintDays: Overall!$B$10
Name HorizonYears: Overall!$B$11
Name CostEscalation: Overall!$B$12
Name HorizonFactor: Overall!$B$13
Name Contingency: Overall!$B$14
Name FxRate: Overall!$B$15
Name ClaudeFxRate: Overall!$B$16
Name LastActual: Sprints!$C$3

Sheet Overall
A1: Sentral Holdings corporate banking portal (Project Gateway): AI-assisted build and 3-year run
A2: All costs in USD. Cloud: Azure retail list prices in westus3 fetched 2026-09-30, no discounts or reservations. Blue cells are inputs; black cells are formulas; green cells link to other sheets.
A3: Inputs
A4: Input | B4: Value
A5: Days of delivery (working days) | B5: 75
A6: Working days per month | B6: 21
A7: Months of delivery | B7: =DeliveryDays/WorkingDaysPerMonth
A8: Hours per month (always-on services) | B8: 730
A9: Delivery start date (optional; dates the epics and sprints) | B9: 46265
A10: Working days per sprint | B10: 10
A11: Years of run after go-live (3 to 5) | B11: 3
A12: Yearly increase in run costs | B12: 0.03
A13: Run years, with the yearly increase | B13: =IF(CostEscalation=0,HorizonYears,((1+CostEscalation)^HorizonYears-1)/CostEscalation)
A14: Contingency | B14: 0.1
A15: Exchange rate (1 USD = x USD) | B15: 1
A16: Exchange rate for Claude prices (1 USD = x USD) | B16: 1
A18: Delivery team (build)
A19: Role | B19: Day rate (USD) | C19: Employees | D19: Days on delivery | E19: Allocation | F19: Mandays | G19: Cost (USD) | H19: Cited from
A20: Delivery lead | B20: =VLOOKUP(A20,'Rate Card'!$A$5:$B$50,2,FALSE) | C20: 1 | D20: =DeliveryDays | E20: 0.5 | F20: =C20*D20*E20 | G20: =F20*B20 | H20: assumption: AI-assisted delivery team for 31 stories over 75 working days; synthetic portfolio figure, owner request 2026-09-30
A21: Solution architect | B21: =VLOOKUP(A21,'Rate Card'!$A$5:$B$50,2,FALSE) | C21: 1 | D21: =DeliveryDays | E21: 0.5 | F21: =C21*D21*E21 | G21: =F21*B21 | H21: assumption: AI-assisted delivery team for 31 stories over 75 working days; synthetic portfolio figure, owner request 2026-09-30
A22: Full-stack developer | B22: =VLOOKUP(A22,'Rate Card'!$A$5:$B$50,2,FALSE) | C22: 1 | D22: =DeliveryDays | E22: 1 | F22: =C22*D22*E22 | G22: =F22*B22 | H22: _bmad-output/specs/spec-corporate-portal-poc/SPEC.md Fluent UI with five screens
A23: Cloud / DevOps engineer | B23: =VLOOKUP(A23,'Rate Card'!$A$5:$B$50,2,FALSE) | C23: 1 | D23: =DeliveryDays | E23: 1 | F23: =C23*D23*E23 | G23: =F23*B23 | H23: _bmad-output/specs/spec-corporate-portal-poc/SPEC.md CAP-10
A24: Data engineer | B24: =VLOOKUP(A24,'Rate Card'!$A$5:$B$50,2,FALSE) | C24: 1 | D24: =DeliveryDays | E24: 1 | F24: =C24*D24*E24 | G24: =F24*B24 | H24: _bmad-output/specs/spec-corporate-portal-poc/SPEC.md CAP-6
A25: QA engineer | B25: =VLOOKUP(A25,'Rate Card'!$A$5:$B$50,2,FALSE) | C25: 1 | D25: =DeliveryDays | E25: 0.5 | F25: =C25*D25*E25 | G25: =F25*B25 | H25: assumption: AI-assisted delivery team for 31 stories over 75 working days; synthetic portfolio figure, owner request 2026-09-30
B26: =IF(A26="","",VLOOKUP(A26,'Rate Card'!$A$5:$B$50,2,FALSE)) | F26: =IF(A26="","",C26*D26*E26) | G26: =IF(A26="","",F26*B26)
B27: =IF(A27="","",VLOOKUP(A27,'Rate Card'!$A$5:$B$50,2,FALSE)) | F27: =IF(A27="","",C27*D27*E27) | G27: =IF(A27="","",F27*B27)
B28: =IF(A28="","",VLOOKUP(A28,'Rate Card'!$A$5:$B$50,2,FALSE)) | F28: =IF(A28="","",C28*D28*E28) | G28: =IF(A28="","",F28*B28)
A29: Total | C29: =SUM(C20:C28) | F29: =SUM(F20:F28) | G29: =SUM(G20:G28)
A31: Run support (OPEX): IT support and maintenance after go-live
A32: Role | B32: Day rate (USD) | C32: Mandays per year | D32: Cost per year (USD) | E32: Cited from
A33: Support engineer | B33: =VLOOKUP(A33,'Rate Card'!$A$5:$B$50,2,FALSE) | C33: 60 | D33: =C33*B33 | E33: assumption: L2 support, patching and on-call for the portal; synthetic portfolio figure, owner request 2026-09-30
A34: Cloud / DevOps engineer | B34: =VLOOKUP(A34,'Rate Card'!$A$5:$B$50,2,FALSE) | C34: 30 | D34: =C34*B34 | E34: assumption: AKS, Istio, Kong and Vault upgrades in two regions; synthetic portfolio figure, owner request 2026-09-30
A35: Data engineer | B35: =VLOOKUP(A35,'Rate Card'!$A$5:$B$50,2,FALSE) | C35: 20 | D35: =C35*B35 | E35: assumption: pipeline care and model retraining; synthetic portfolio figure, owner request 2026-09-30
B36: =IF(A36="","",VLOOKUP(A36,'Rate Card'!$A$5:$B$50,2,FALSE)) | D36: =IF(A36="","",C36*B36)
B37: =IF(A37="","",VLOOKUP(A37,'Rate Card'!$A$5:$B$50,2,FALSE)) | D37: =IF(A37="","",C37*B37)
B38: =IF(A38="","",VLOOKUP(A38,'Rate Card'!$A$5:$B$50,2,FALSE)) | D38: =IF(A38="","",C38*B38)
A39: Total | C39: =SUM(C33:C38) | D39: =SUM(D33:D38)
A41: Cost summary
A42: Item | B42: Monthly (USD) | C42: Months in delivery | D42: Delivery cost (USD) | E42: Run months per year | F42: Run cost per year (USD) | G42: Run cost over the horizon (USD) | H42: Total (USD) | I42: From
A43: Dev environment | B43: ='Dev'!$I$23 | C43: =DeliveryMonths | D43: =B43*C43 | E43: 12 | F43: =B43*E43 | G43: =F43*HorizonFactor | H43: =D43+G43 | I43: Dev sheet
...

Sheet Multi-Year
A1: Multi-year view
A2: In USD. Build is the delivery; each year after go-live carries the run costs, raised by the yearly increase, and the revenue given for it. Years past the horizon (Overall input) show zero. Contingency applies to every cost.
A4: Category | B4: Item | C4: Build | D4: Year 1 | E4: Year 2 | F4: Year 3 | G4: Year 4 | H4: Year 5 | I4: Total
A5: Revenue | B5: =IF('Revenue'!$B$5="","(spare revenue row)",'Revenue'!$B$5) | C5: 0 | D5: =IF(1<=HorizonYears,'Revenue'!D$5,0) | E5: =IF(2<=HorizonYears,'Revenue'!E$5,0) | F5: =IF(3<=HorizonYears,'Revenue'!F$5,0) | G5: =IF(4<=HorizonYears,'Revenue'!G$5,0) | H5: =IF(5<=HorizonYears,'Revenue'!H$5,0) | I5: =SUM(C5:H5)
A6: Revenue | B6: =IF('Revenue'!$B$6="","(spare revenue row)",'Revenue'!$B$6) | C6: 0 | D6: =IF(1<=HorizonYears,'Revenue'!D$6,0) | E6: =IF(2<=HorizonYears,'Revenue'!E$6,0) | F6: =IF(3<=HorizonYears,'Revenue'!F$6,0) | G6: =IF(4<=HorizonYears,'Revenue'!G$6,0) | H6: =IF(5<=HorizonYears,'Revenue'!H$6,0) | I6: =SUM(C6:H6)
A7: Revenue | B7: =IF('Revenue'!$B$7="","(spare revenue row)",'Revenue'!$B$7) | C7: 0 | D7: =IF(1<=HorizonYears,'Revenue'!D$7,0) | E7: =IF(2<=HorizonYears,'Revenue'!E$7,0) | F7: =IF(3<=HorizonYears,'Revenue'!F$7,0) | G7: =IF(4<=HorizonYears,'Revenue'!G$7,0) | H7: =IF(5<=HorizonYears,'Revenue'!H$7,0) | I7: =SUM(C7:H7)
A8: Cost | B8: Build: delivery team, environments during delivery, one-off costs, Claude usage | C8: ='Overall'!$D$52 | D8: 0 | E8: 0 | F8: 0 | G8: 0 | H8: 0 | I8: =SUM(C8:H8)
A9: Cost | B9: Dev environment (run) | C9: 0 | D9: =IF(1<=HorizonYears,'Overall'!$F$43*(1+CostEscalation)^0,0) | E9: =IF(2<=HorizonYears,'Overall'!$F$43*(1+CostEscalation)^1,0) | F9: =IF(3<=HorizonYears,'Overall'!$F$43*(1+CostEscalation)^2,0) | G9: =IF(4<=HorizonYears,'Overall'!$F$43*(1+CostEscalation)^3,0) | H9: =IF(5<=HorizonYears,'Overall'!$F$43*(1+CostEscalation)^4,0) | I9: =SUM(C9:H9)
A10: Cost | B10: Test environment (run) | C10: 0 | D10: =IF(1<=HorizonYears,'Overall'!$F$44*(1+CostEscalation)^0,0) | E10: =IF(2<=HorizonYears,'Overall'!$F$44*(1+CostEscalation)^1,0) | F10: =IF(3<=HorizonYears,'Overall'!$F$44*(1+CostEscalation)^2,0) | G10: =IF(4<=HorizonYears,'Overall'!$F$44*(1+CostEscalation)^3,0) | H10: =IF(5<=HorizonYears,'Overall'!$F$44*(1+CostEscalation)^4,0) | I10: =SUM(C10:H10)
A11: Cost | B11: UAT environment (run) | C11: 0 | D11: =IF(1<=HorizonYears,'Overall'!$F$45*(1+CostEscalation)^0,0) | E11: =IF(2<=HorizonYears,'Overall'!$F$45*(1+CostEscalation)^1,0) | F11: =IF(3<=HorizonYears,'Overall'!$F$45*(1+CostEscalation)^2,0) | G11: =IF(4<=HorizonYears,'Overall'!$F$45*(1+CostEscalation)^3,0) | H11: =IF(5<=HorizonYears,'Overall'!$F$45*(1+CostEscalation)^4,0) | I11: =SUM(C11:H11)
A12: Cost | B12: Prod environment (run) | C12: 0 | D12: =IF(1<=HorizonYears,'Overall'!$F$46*(1+CostEscalation)^0,0) | E12: =IF(2<=HorizonYears,'Overall'!$F$46*(1+CostEscalation)^1,0) | F12: =IF(3<=HorizonYears,'Overall'!$F$46*(1+CostEscalation)^2,0) | G12: =IF(4<=HorizonYears,'Overall'!$F$46*(1+CostEscalation)^3,0) | H12: =IF(5<=HorizonYears,'Overall'!$F$46*(1+CostEscalation)^4,0) | I12: =SUM(C12:H12)
A13: Cost | B13: Run support (OPEX) | C13: 0 | D13: =IF(1<=HorizonYears,'Overall'!$F$48*(1+CostEscalation)^0,0) | E13: =IF(2<=HorizonYears,'Overall'!$F$48*(1+CostEscalation)^1,0) | F13: =IF(3<=HorizonYears,'Overall'!$F$48*(1+CostEscalation)^2,0) | G13: =IF(4<=HorizonYears,'Overall'!$F$48*(1+CostEscalation)^3,0) | H13: =IF(5<=HorizonYears,'Overall'!$F$48*(1+CostEscalation)^4,0) | I13: =SUM(C13:H13)
A14: Cost | B14: Recurring run costs | C14: 0 | D14: =IF(1<=HorizonYears,'Overall'!$F$49*(1+CostEscalation)^0,0) | E14: =IF(2<=HorizonYears,'Overall'!$F$49*(1+CostEscalation)^1,0) | F14: =IF(3<=HorizonYears,'Overall'!$F$49*(1+CostEscalation)^2,0) | G14: =IF(4<=HorizonYears,'Overall'!$F$49*(1+CostEscalation)^3,0) | H14: =IF(5<=HorizonYears,'Overall'!$F$49*(1+CostEscalation)^4,0) | I14: =SUM(C14:H14)
A15: Contingency | B15: Contingency on every cost | C15: =SUMIF($A$5:$A$14,"Cost",C5:C14)*Contingency | D15: =SUMIF($A$5:$A$14,"Cost",D5:D14)*Contingency | E15: =SUMIF($A$5:$A$14,"Cost",E5:E14)*Contingency | F15: =SUMIF($A$5:$A$14,"Cost",F5:F14)*Contingency | G15: =SUMIF($A$5:$A$14,"Cost",G5:G14)*Contingency | H15: =SUMIF($A$5:$A$14,"Cost",H5:H14)*Contingency | I15: =SUM(C15:H15)
A16: Total revenue | C16: =SUMIF($A$5:$A$15,"Revenue",C5:C15) | D16: =SUMIF($A$5:$A$15,"Revenue",D5:D15) | E16: =SUMIF($A$5:$A$15,"Revenue",E5:E15) | F16: =SUMIF($A$5:$A$15,"Revenue",F5:F15) | G16: =SUMIF($A$5:$A$15,"Revenue",G5:G15) | H16: =SUMIF($A$5:$A$15,"Revenue",H5:H15) | I16: =SUMIF($A$5:$A$15,"Revenue",I5:I15)
A17: Total costs | C17: =SUMIF($A$5:$A$15,"Cost",C5:C15)+SUMIF($A$5:$A$15,"Contingency",C5:C15) | D17: =SUMIF($A$5:$A$15,"Cost",D5:D15)+SUMIF($A$5:$A$15,"Contingency",D5:D15) | E17: =SUMIF($A$5:$A$15,"Cost",E5:E15)+SUMIF($A$5:$A$15,"Contingency",E5:E15) | F17: =SUMIF($A$5:$A$15,"Cost",F5:F15)+SUMIF($A$5:$A$15,"Contingency",F5:F15) | G17: =SUMIF($A$5:$A$15,"Cost",G5:G15)+SUMIF($A$5:$A$15,"Contingency",G5:G15) | H17: =SUMIF($A$5:$A$15,"Cost",H5:H15)+SUMIF($A$5:$A$15,"Contingency",H5:H15) | I17: =SUMIF($A$5:$A$15,"Cost",I5:I15)+SUMIF($A$5:$A$15,"Contingency",I5:I15)
A18: Net | C18: =C16-C17 | D18: =D16-D17 | E18: =E16-E17 | F18: =F16-F17 | G18: =G16-G17 | H18: =H16-H17 | I18: =I16-I17
A19: Cumulative net | C19: =C18 | D19: =C19+D18 | E19: =D19+E18 | F19: =E19+F18 | G19: =F19+G18 | H19: =G19+H18 | I19: =H19
A21: Payback | B21: =IF(C19>=0,"Build",IF(D19>=0,"Year 1",IF(E19>=0,"Year 2",IF(F19>=0,"Year 3",IF(G19>=0,"Year 4",IF(H19>=0,"Year 5","beyond the horizon"))))))
A22: Return on cost (net / costs) | B22: =IF(I17=0,"",I18/I17)

Sheet Epics
A1: Epics: deliverables, forecast and actual
A2: In USD. Forecast: each epic takes a share of the build in proportion to its planned working days (that share of the delivery team and of the environments during delivery), plus the one-off costs tagged to it and its Claude API budget; dates run the epics one after another from the delivery start date. Actual: enter or keep the actual start and end dates; actual working days, the Claude API actual from the ledger, and team and infra scaled by actual / planned days (same team and rates) unless you enter the timesheet team cost. Blue cells are inputs; add an epic in a spare row.
A4: Epic | B4: Name | C4: Deliverables | D4: Planned days | E4: Planned weeks | F4: Planned start | G4: Planned end | H4: Share of build | I4: Team mandays | J4: Team cost (USD) | K4: Infra cost (USD) | L4: Other costs (USD) | M4: Claude API budget (USD) | N4: Forecast total (USD) | O4: Actual start | P4: Actual end | Q4: Actual days | R4: Days variance | S4: Days variance % | T4: Claude API actual (USD) | U4: Actual team cost, timesheets (USD) | V4: Actual total (USD) | W4: Cost variance (USD) | X4: Cited from
A5: 1 | B5: Secure platform foundation | C5: 1.1 Terraform resource groups and least-privilege Jenkins identity 1.2 AKS with Node Auto Provisioning, Istio mTLS STRICT and Kong ingress 1.3 Vault with Key Vault auto-unseal and secret-free services 1.4 Parallel microservice image builds with Kaniko on Jenkins agents 1.5 Private endpoints and private DNS for lake, SQL, Key Vault and Event Hubs 1.6 Cost guardrails: Databricks cluster policy and clean terraform destroy | D5: 12 | E5: =IF(D5="","",D5/5) | F5: =IF(OR(D5="",ProjectStart=""),"",ProjectStart) | G5: =IF(F5="","",WORKDAY(F5,D5-1)) | H5: =IF(D5="","",D5/SUM($D$5:$D$13)) | I5: =IF(D5="","",H5*'Overall'!$F$29) | J5: =IF(D5="","",H5*'Overall'!$G$29) | K5: =IF(D5="","",H5*('Overall'!$D$43+'Overall'!$D$44+'Overall'!$D$45+'Overall'!$D$46)) | L5: =IF(A5="","",SUMIFS('Other Costs'!$C$5:$C$9,'Other Costs'!$F$5:$F$9,A5)) | M5: 55 | N5: =IF(D5="","",J5+K5+L5+N(M5)) | O5: 46265 | P5: 46281 | Q5: =IF(OR(D5="",O5="",P5=""),"",NETWORKDAYS(O5,P5)) | R5: =IF(Q5="","",Q5-D5) | S5: =IF(Q5="","",Q5/D5-1) | T5: =IF(A5="","",SUMIFS('Claude Usage Detail'!$P$5:$P$43,'Claude Usage Detail'!$C$5:$C$43,A5&".*")) | V5: =IF(Q5="","",IF(U5="",J5*Q5/D5,U5)+K5*Q5/D5+L5+N(T5)) | W5: =IF(V5="","",V5-N5) | X5: _bmad-output/specs/spec-corporate-portal-poc/SPEC.md CAP-10
A6: 2 | B6: Treasurer portal and maker-checker payments | C6: 2.1 Entra External ID sign-in and company-scoped sessions 2.2 Row-level security for company isolation with blocked-access logging 2.3 Cash position and liquidity dashboard from the serving schema 2.4 Accounts, balances and transactions 2.5 Payment creation with maker-checker approval and execution 2.6 Portal chrome: region badge, synthetic-data banner and error states | D6: 14 | E6: =IF(D6="","",D6/5) | F6: =IF(OR(D6="",ProjectStart=""),"",WORKDAY(G5,1)) | G6: =IF(F6="","",WORKDAY(F6,D6-1)) | H6: =IF(D6="","",D6/SUM($D$5:$D$13)) | I6: =IF(D6="","",H6*'Overall'!$F$29) | J6: =IF(D6="","",H6*'Overall'!$G$29) | K6: =IF(D6="","",H6*('Overall'!$D$43+'Overall'!$D$44+'Overall'!$D$45+'Overall'!$D$46)) | L6: =IF(A6="","",SUMIFS('Other Costs'!$C$5:$C$9,'Other Costs'!$F$5:$F$9,A6)) | M6: 65 | N6: =IF(D6="","",J6+K6+L6+N(M6)) | O6: 46282 | Q6: =IF(OR(D6="",O6="",P6=""),"",NETWORKDAYS(O6,P6)) | R6: =IF(Q6="","",Q6-D6) | S6: =IF(Q6="","",Q6/D6-1) | T6: =IF(A6="","",SUMIFS('Claude Usage Detail'!$P$5:$P$43,'Claude Usage Detail'!$C$5:$C$43,A6&".*")) | V6: =IF(Q6="","",IF(U6="",J6*Q6/D6,U6)+K6*Q6/D6+L6+N(T6)) | W6: =IF(V6="","",V6-N6) | X6: _bmad-output/specs/spec-corporate-portal-poc/SPEC.md CAP-4
A7: 3 | B7: Ledger events through the medallion lake | C7: 3.1 Seeded synthetic world: companies, payroll cycles, suppliers and planted anomalies 3.2 Outbox relay from the SQL ledger to Event Hubs 3.3 Bronze ingestion from the Event Hubs Kafka endpoint 3.4 Silver and gold Delta transforms with serving-schema write-back 3.5 Behind-the-scenes stage panel | D7: 12 | E7: =IF(D7="","",D7/5) | F7: =IF(OR(D7="",ProjectStart=""),"",WORKDAY(G6,1)) | G7: =IF(F7="","",WORKDAY(F7,D7-1)) | H7: =IF(D7="","",D7/SUM($D$5:$D$13)) | I7: =IF(D7="","",H7*'Overall'!$F$29) | J7: =IF(D7="","",H7*'Overall'!$G$29) | K7: =IF(D7="","",H7*('Overall'!$D$43+'Overall'!$D$44+'Overall'!$D$45+'Overall'!$D$46)) | L7: =IF(A7="","",SUMIFS('Other Costs'!$C$5:$C$9,'Other Costs'!$F$5:$F$9,A7)) | M7: 55 | N7: =IF(D7="","",J7+K7+L7+N(M7)) | Q7: =IF(OR(D7="",O7="",P7=""),"",NETWORKDAYS(O7,P7)) | R7: =IF(Q7="","",Q7-D7) | S7: =IF(Q7="","",Q7/D7-1) | T7: =IF(A7="","",SUMIFS('Claude Usage Detail'!$P$5:$P$43,'Claude Usage Detail'!$C$5:$C$43,A7&".*")) | V7: =IF(Q7="","",IF(U7="",J7*Q7/D7,U7)+K7*Q7/D7+L7+N(T7)) | W7: =IF(V7="","",V7-N7) | X7: _bmad-output/specs/spec-corporate-portal-poc/SPEC.md CAP-5
A8: 4 | B8: Lineage and ML cash intelligence | C8: 4.1 Unity Catalog lineage from gold back to the Event Hubs source 4.2 Cash forecast model tracked in MLflow and registered in Unity Catalog 4.3 Isolation Forest payment anomaly detection 4.4 Batch scoring into forecasts and anomalies tables 4.5 Forecast screen and anomaly flags in the portal | D8: 12 | E8: =IF(D8="","",D8/5) | F8: =IF(OR(D8="",ProjectStart=""),"",WORKDAY(G7,1)) | G8: =IF(F8="","",WORKDAY(F8,D8-1)) | H8: =IF(D8="","",D8/SUM($D$5:$D$13)) | I8: =IF(D8="","",H8*'Overall'!$F$29) | J8: =IF(D8="","",H8*'Overall'!$G$29) | K8: =IF(D8="","",H8*('Overall'!$D$43+'Overall'!$D$44+'Overall'!$D$45+'Overall'!$D$46)) | L8: =IF(A8="","",SUMIFS('Other Costs'!$C$5:$C$9,'Other Costs'!$F$5:$F$9,A8)) | M8: 60 | N8: =IF(D8="","",J8+K8+L8+N(M8)) | Q8: =IF(OR(D8="",O8="",P8=""),"",NETWORKDAYS(O8,P8)) | R8: =IF(Q8="","",Q8-D8) | S8: =IF(Q8="","",Q8/D8-1) | T8: =IF(A8="","",SUMIFS('Claude Usage Detail'!$P$5:$P$43,'Claude Usage Detail'!$C$5:$C$43,A8&".*")) | V8: =IF(Q8="","",IF(U8="",J8*Q8/D8,U8)+K8*Q8/D8+L8+N(T8)) | W8: =IF(V8="","",V8-N8) | X8: _bmad-output/specs/spec-corporate-portal-poc/SPEC.md CAP-7
A9: 5 | B9: Multi-region resilience | C9: 5.1 Region-2 AKS from the same Terraform module 5.2 Front Door origins, health probes and Front Door-only ingress 5.3 SQL failover group behind a Terraform flag 5.4 Grafana requests-per-second by region 5.5 Regional failover drill and runbook | D9: 10 | E9: =IF(D9="","",D9/5) | F9: =IF(OR(D9="",ProjectStart=""),"",WORKDAY(G8,1)) | G9: =IF(F9="","",WORKDAY(F9,D9-1)) | H9: =IF(D9="","",D9/SUM($D$5:$D$13)) | I9: =IF(D9="","",H9*'Overall'!$F$29) | J9: =IF(D9="","",H9*'Overall'!$G$29) | K9: =IF(D9="","",H9*('Overall'!$D$43+'Overall'!$D$44+'Overall'!$D$45+'Overall'!$D$46)) | L9: =IF(A9="","",SUMIFS('Other Costs'!$C$5:$C$9,'Other Costs'!$F$5:$F$9,A9)) | M9: 45 | N9: =IF(D9="","",J9+K9+L9+N(M9)) | Q9: =IF(OR(D9="",O9="",P9=""),"",NETWORKDAYS(O9,P9)) | R9: =IF(Q9="","",Q9-D9) | S9: =IF(Q9="","",Q9/D9-1) | T9: =IF(A9="","",SUMIFS('Claude Usage Detail'!$P$5:$P$43,'Claude Usage Detail'!$C$5:$C$43,A9&".*")) | V9: =IF(Q9="","",IF(U9="",J9*Q9/D9,U9)+K9*Q9/D9+L9+N(T9)) | W9: =IF(V9="","",V9-N9) | X9: _bmad-output/specs/spec-corporate-portal-poc/SPEC.md CAP-12
A10: 6 | B10: Security assurance, UAT and go-live | C10: 6.1 Security controls evidence pack for the CISO review 6.2 PDPA data-protection assessment and penetration test remediation 6.3 UAT with Group Treasury and business sign-off 6.4 CAB approval, production cut-over and hypercare | D10: 15 | E10: =IF(D10="","",D10/5) | F10: =IF(OR(D10="",ProjectStart=""),"",WORKDAY(G9,1)) | G10: =IF(F10="","",WORKDAY(F10,D10-1)) | H10: =IF(D10="","",D10/SUM($D$5:$D$13)) | I10: =IF(D10="","",H10*'Overall'!$F$29) | J10: =IF(D10="","",H10*'Overall'!$G$29) | K10: =IF(D10="","",H10*('Overall'!$D$43+'Overall'!$D$44+'Overall'!$D$45+'Overall'!$D$46)) | L10: =IF(A10="","",SUMIFS('Other Costs'!$C$5:$C$9,'Other Costs'!$F$5:$F$9,A10)) | M10: 35 | N10: =IF(D10="","",J10+K10+L10+N(M10)) | Q10: =IF(OR(D10="",O10="",P10=""),"",NETWORKDAYS(O10,P10)) | R10: =IF(Q10="","",Q10-D10) | S10: =IF(Q10="","",Q10/D10-1) | T10: =IF(A10="","",SUMIFS('Claude Usage Detail'!$P$5:$P$43,'Claude Usage Detail'!$C$5:$C$43,A10&".*")) | V10: =IF(Q10="","",IF(U10="",J10*Q10/D10,U10)+K10*Q10/D10+L10+N(T10)) | W10: =IF(V10="","",V10-N10) | X10: _bmad-output/specs/spec-corporate-portal-poc/SPEC.md CAP-14
E11: =IF(D11="","",D11/5) | F11: =IF(OR(D11="",ProjectStart=""),"",WORKDAY(G10,1)) | G11: =IF(F11="","",WORKDAY(F11,D11-1)) | H11: =IF(D11="","",D11/SUM($D$5:$D$13)) | I11: =IF(D11="","",H11*'Overall'!$F$29) | J11: =IF(D11="","",H11*'Overall'!$G$29) | K11: =IF(D11="","",H11*('Overall'!$D$43+'Overall'!$D$44+'Overall'!$D$45+'Overall'!$D$46)) | L11: =IF(A11="","",SUMIFS('Other Costs'!$C$5:$C$9,'Other Costs'!$F$5:$F$9,A11)) | N11: =IF(D11="","",J11+K11+L11+N(M11)) | Q11: =IF(OR(D11="",O11="",P11=""),"",NETWORKDAYS(O11,P11)) | R11: =IF(Q11="","",Q11-D11) | S11: =IF(Q11="","",Q11/D11-1) | T11: =IF(A11="","",SUMIFS('Claude Usage Detail'!$P$5:$P$43,'Claude Usage Detail'!$C$5:$C$43,A11&".*")) | V11: =IF(Q11="","",IF(U11="",J11*Q11/D11,U11)+K11*Q11/D11+L11+N(T11)) | W11: =IF(V11="","",V11-N11)
E12: =IF(D12="","",D12/5) | F12: =IF(OR(D12="",ProjectStart=""),"",WORKDAY(G11,1)) | G12: =IF(F12="","",WORKDAY(F12,D12-1)) | H12: =IF(D12="","",D12/SUM($D$5:$D$13)) | I12: =IF(D12="","",H12*'Overall'!$F$29) | J12: =IF(D12="","",H12*'Overall'!$G$29) | K12: =IF(D12="","",H12*('Overall'!$D$43+'Overall'!$D$44+'Overall'!$D$45+'Overall'!$D$46)) | L12: =IF(A12="","",SUMIFS('Other Costs'!$C$5:$C$9,'Other Costs'!$F$5:$F$9,A12)) | N12: =IF(D12="","",J12+K12+L12+N(M12)) | Q12: =IF(OR(D12="",O12="",P12=""),"",NETWORKDAYS(O12,P12)) | R12: =IF(Q12="","",Q12-D12) | S12: =IF(Q12="","",Q12/D12-1) | T12: =IF(A12="","",SUMIFS('Claude Usage Detail'!$P$5:$P$43,'Claude Usage Detail'!$C$5:$C$43,A12&".*")) | V12: =IF(Q12="","",IF(U12="",J12*Q12/D12,U12)+K12*Q12/D12+L12+N(T12)) | W12: =IF(V12="","",V12-N12)
E13: =IF(D13="","",D13/5) | F13: =IF(OR(D13="",ProjectStart=""),"",WORKDAY(G12,1)) | G13: =IF(F13="","",WORKDAY(F13,D13-1)) | H13: =IF(D13="","",D13/SUM($D$5:$D$13)) | I13: =IF(D13="","",H13*'Overall'!$F$29) | J13: =IF(D13="","",H13*'Overall'!$G$29) | K13: =IF(D13="","",H13*('Overall'!$D$43+'Overall'!$D$44+'Overall'!$D$45+'Overall'!$D$46)) | L13: =IF(A13="","",SUMIFS('Other Costs'!$C$5:$C$9,'Other Costs'!$F$5:$F$9,A13)) | N13: =IF(D13="","",J13+K13+L13+N(M13)) | Q13: =IF(OR(D13="",O13="",P13=""),"",NETWORKDAYS(O13,P13)) | R13: =IF(Q13="","",Q13-D13) | S13: =IF(Q13="","",Q13/D13-1) | T13: =IF(A13="","",SUMIFS('Claude Usage Detail'!$P$5:$P$43,'Claude Usage Detail'!$C$5:$C$43,A13&".*")) | V13: =IF(Q13="","",IF(U13="",J13*Q13/D13,U13)+K13*Q13/D13+L13+N(T13)) | W13: =IF(V13="","",V13-N13)
A14: Total | D14: =SUM(D5:D13) | I14: =SUM(I5:I13) | J14: =SUM(J5:J13) | K14: =SUM(K5:K13) | L14: =SUM(L5:L13) | M14: =SUM(M5:M13) | N14: =SUM(N5:N13) | Q14: =SUM(Q5:Q13) | R14: =SUM(R5:R13) | S14: =IF(Q14=0,"",Q14/SUMIFS(D5:D13,Q5:Q13,">0")-1) | T14: =SUM(T5:T13) | U14: =SUM(U5:U13) | V14: =SUM(V5:V13) | W14: =SUM(W5:W13)
A16: =IF(D14=DeliveryDays,"The planned epics add up to the days of delivery.","The planned epics add up to "&D14&" working days; the days of delivery input is "&DeliveryDays&". Costs are shared by planned epic days either way.")

Sheet Sprints
A1: Sprints: forecast and actual
A2: In USD. Every sprint is a timebox of the Overall input 'Working days per sprint' from the delivery start date. Forecast: the sprint's planned working days (the days of delivery, sprint by sprint) at the delivery team's and the environments' daily cost, plus any Claude API budget. Actual, up to the last actual activity (the latest completed story or day of Claude usage): the days worked in the sprint, the stories completed, the Claude API cost on its days, and the team at the days worked unless timesheets are entered. Sprints past the plan appear when work ran over. Blue cells are inputs.
A3: Last actual activity | C3: =IF(MAX(MAXIFS('Project Timeline'!$F$5:$F$89,'Project Timeline'!$A$5:$A$89,"story"),MAX('Claude Usage Daily'!$A$5:$A$115))=0,"",MAX(MAXIFS('Project Timeline'!$F$5:$F$89,'Project Timeline'!$A$5:$A$89,"story"),MAX('Claude Usage Daily'!$A$5:$A$115)))
A4: Sprint | B4: Start | C4: End | D4: Planned days | E4: Planned stories | F4: Team cost (USD) | G4: Infra cost (USD) | H4: Claude API budget (USD) | I4: Forecast total (USD) | J4: Days worked | K4: Stories done | L4: Stories done (list) | M4: Claude API actual (USD) | N4: Actual team cost, timesheets (USD) | O4: Actual total (USD) | P4: Cost variance (USD)
A5: 1 | B5: =IF(OR(D5="",ProjectStart=""),"",WORKDAY(ProjectStart,(1-1)*SprintDays)) | C5: =IF(B5="","",WORKDAY(B5,SprintDays-1)) | D5: =IF(OR(MIN(SprintDays,MAX(0,DeliveryDays-(1-1)*SprintDays))>0,AND(ProjectStart<>"",LastActual<>"",WORKDAY(ProjectStart,(1-1)*SprintDays)<=N(LastActual))),MIN(SprintDays,MAX(0,DeliveryDays-(1-1)*SprintDays)),"") | E5: 1.1 Terraform resource groups and least-privilege Jenkins identity 1.2 AKS with Node Auto Provisioning, Istio mTLS STRICT and Kong ingress 1.3 Vault with Key Vault auto-unseal and secret-free services 1.4 Parallel microservice image builds with Kaniko on Jenkins agents 1.5 Private endpoints and private DNS for lake, SQL, Key Vault and Event Hubs | F5: =IF(D5="","",D5*'Overall'!$G$29/DeliveryDays) | G5: =IF(D5="","",D5*('Overall'!$D$43+'Overall'!$D$44+'Overall'!$D$45+'Overall'!$D$46)/DeliveryDays) | I5: =IF(D5="","",F5+G5+N(H5)) | J5: =IF(OR(B5="",LastActual="",B5>N(LastActual)),"",NETWORKDAYS(B5,MIN(C5,LastActual))) | K5: =IF(J5="","",COUNTIFS('Project Timeline'!$A$5:$A$89,"story",'Project Timeline'!$F$5:$F$89,">="&B5,'Project Timeline'!$F$5:$F$89,"<="&C5)) | L5: 1-1-terraform-resource-groups-and 1-2-aks-with-node-auto 1-3-vault-with-key-vault 1-4-parallel-microservice-image-builds | M5: =IF(J5="","",SUMIFS('Claude Usage Daily'!$O$5:$O$115,'Claude Usage Daily'!$A$5:$A$115,">="&B5,'Claude Usage Daily'!$A$5:$A$115,"<="&C5)) | O5: =IF(J5="","",IF(N5="",J5*'Overall'!$G$29/DeliveryDays,N5)+J5*('Overall'!$D$43+'Overall'!$D$44+'Overall'!$D$45+'Overall'!$D$46)/DeliveryDays+N(M5)) | P5: =IF(O5="","",O5-N(I5))
A6: 2 | B6: =IF(OR(D6="",ProjectStart=""),"",WORKDAY(ProjectStart,(2-1)*SprintDays)) | C6: =IF(B6="","",WORKDAY(B6,SprintDays-1)) | D6: =IF(OR(MIN(SprintDays,MAX(0,DeliveryDays-(2-1)*SprintDays))>0,AND(ProjectStart<>"",LastActual<>"",WORKDAY(ProjectStart,(2-1)*SprintDays)<=N(LastActual))),MIN(SprintDays,MAX(0,DeliveryDays-(2-1)*SprintDays)),"") | E6: 1.6 Cost guardrails: Databricks cluster policy and clean terraform destroy 2.1 Entra External ID sign-in and company-scoped sessions 2.2 Row-level security for company isolation with blocked-access logging 2.3 Cash position and liquidity dashboard from the serving schema 2.4 Accounts, balances and transactions | F6: =IF(D6="","",D6*'Overall'!$G$29/DeliveryDays) | G6: =IF(D6="","",D6*('Overall'!$D$43+'Overall'!$D$44+'Overall'!$D$45+'Overall'!$D$46)/DeliveryDays) | I6: =IF(D6="","",F6+G6+N(H6)) | J6: =IF(OR(B6="",LastActual="",B6>N(LastActual)),"",NETWORKDAYS(B6,MIN(C6,LastActual))) | K6: =IF(J6="","",COUNTIFS('Project Timeline'!$A$5:$A$89,"story",'Project Timeline'!$F$5:$F$89,">="&B6,'Project Timeline'!$F$5:$F$89,"<="&C6)) | L6: 1-5-private-endpoints-and-private 1-6-cost-guardrails-databricks-cluster 2-1-entra-external-id-sign-in 2-2-row-level-security-for-company | M6: =IF(J6="","",SUMIFS('Claude Usage Daily'!$O$5:$O$115,'Claude Usage Daily'!$A$5:$A$115,">="&B6,'Claude Usage Daily'!$A$5:$A$115,"<="&C6)) | O6: =IF(J6="","",IF(N6="",J6*'Overall'!$G$29/DeliveryDays,N6)+J6*('Overall'!$D$43+'Overall'!$D$44+'Overall'!$D$45+'Overall'!$D$46)/DeliveryDays+N(M6)) | P6: =IF(O6="","",O6-N(I6))
A7: 3 | B7: =IF(OR(D7="",ProjectStart=""),"",WORKDAY(ProjectStart,(3-1)*SprintDays)) | C7: =IF(B7="","",WORKDAY(B7,SprintDays-1)) | D7: =IF(OR(MIN(SprintDays,MAX(0,DeliveryDays-(3-1)*SprintDays))>0,AND(ProjectStart<>"",LastActual<>"",WORKDAY(ProjectStart,(3-1)*SprintDays)<=N(LastActual))),MIN(SprintDays,MAX(0,DeliveryDays-(3-1)*SprintDays)),"") | E7: 2.5 Payment creation with maker-checker approval and execution 2.6 Portal chrome: region badge, synthetic-data banner and error states 3.1 Seeded synthetic world: companies, payroll cycles, suppliers and planted anomalies 3.2 Outbox relay from the SQL ledger to Event Hubs | F7: =IF(D7="","",D7*'Overall'!$G$29/DeliveryDays) | G7: =IF(D7="","",D7*('Overall'!$D$43+'Overall'!$D$44+'Overall'!$D$45+'Overall'!$D$46)/DeliveryDays) | I7: =IF(D7="","",F7+G7+N(H7)) | J7: =IF(OR(B7="",LastActual="",B7>N(LastActual)),"",NETWORKDAYS(B7,MIN(C7,LastActual))) | K7: =IF(J7="","",COUNTIFS('Project Timeline'!$A$5:$A$89,"story",'Project Timeline'!$F$5:$F$89,">="&B7,'Project Timeline'!$F$5:$F$89,"<="&C7)) | L7: 2-3-cash-position-and-liquidity | M7: =IF(J7="","",SUMIFS('Claude Usage Daily'!$O$5:$O$115,'Claude Usage Daily'!$A$5:$A$115,">="&B7,'Claude Usage Daily'!$A$5:$A$115,"<="&C7)) | O7: =IF(J7="","",IF(N7="",J7*'Overall'!$G$29/DeliveryDays,N7)+J7*('Overall'!$D$43+'Overall'!$D$44+'Overall'!$D$45+'Overall'!$D$46)/DeliveryDays+N(M7)) | P7: =IF(O7="","",O7-N(I7))
A8: 4 | B8: =IF(OR(D8="",ProjectStart=""),"",WORKDAY(ProjectStart,(4-1)*SprintDays)) | C8: =IF(B8="","",WORKDAY(B8,SprintDays-1)) | D8: =IF(OR(MIN(SprintDays,MAX(0,DeliveryDays-(4-1)*SprintDays))>0,AND(ProjectStart<>"",LastActual<>"",WORKDAY(ProjectStart,(4-1)*SprintDays)<=N(LastActual))),MIN(SprintDays,MAX(0,DeliveryDays-(4-1)*SprintDays)),"") | E8: 3.3 Bronze ingestion from the Event Hubs Kafka endpoint 3.4 Silver and gold Delta transforms with serving-schema write-back 3.5 Behind-the-scenes stage panel 4.1 Unity Catalog lineage from gold back to the Event Hubs source | F8: =IF(D8="","",D8*'Overall'!$G$29/DeliveryDays) | G8: =IF(D8="","",D8*('Overall'!$D$43+'Overall'!$D$44+'Overall'!$D$45+'Overall'!$D$46)/DeliveryDays) | I8: =IF(D8="","",F8+G8+N(H8)) | J8: =IF(OR(B8="",LastActual="",B8>N(LastActual)),"",NETWORKDAYS(B8,MIN(C8,LastActual))) | K8: =IF(J8="","",COUNTIFS('Project Timeline'!$A$5:$A$89,"story",'Project Timeline'!$F$5:$F$89,">="&B8,'Project Timeline'!$F$5:$F$89,"<="&C8)) | M8: =IF(J8="","",SUMIFS('Claude Usage Daily'!$O$5:$O$115,'Claude Usage Daily'!$A$5:$A$115,">="&B8,'Claude Usage Daily'!$A$5:$A$115,"<="&C8)) | O8: =IF(J8="","",IF(N8="",J8*'Overall'!$G$29/DeliveryDays,N8)+J8*('Overall'!$D$43+'Overall'!$D$44+'Overall'!$D$45+'Overall'!$D$46)/DeliveryDays+N(M8)) | P8: =IF(O8="","",O8-N(I8))
A9: 5 | B9: =IF(OR(D9="",ProjectStart=""),"",WORKDAY(ProjectStart,(5-1)*SprintDays)) | C9: =IF(B9="","",WORKDAY(B9,SprintDays-1)) | D9: =IF(OR(MIN(SprintDays,MAX(0,DeliveryDays-(5-1)*SprintDays))>0,AND(ProjectStart<>"",LastActual<>"",WORKDAY(ProjectStart,(5-1)*SprintDays)<=N(LastActual))),MIN(SprintDays,MAX(0,DeliveryDays-(5-1)*SprintDays)),"") | E9: 4.2 Cash forecast model tracked in MLflow and registered in Unity Catalog 4.3 Isolation Forest payment anomaly detection 4.4 Batch scoring into forecasts and anomalies tables 4.5 Forecast screen and anomaly flags in the portal | F9: =IF(D9="","",D9*'Overall'!$G$29/DeliveryDays) | G9: =IF(D9="","",D9*('Overall'!$D$43+'Overall'!$D$44+'Overall'!$D$45+'Overall'!$D$46)/DeliveryDays) | I9: =IF(D9="","",F9+G9+N(H9)) | J9: =IF(OR(B9="",LastActual="",B9>N(LastActual)),"",NETWORKDAYS(B9,MIN(C9,LastActual))) | K9: =IF(J9="","",COUNTIFS('Project Timeline'!$A$5:$A$89,"story",'Project Timeline'!$F$5:$F$89,">="&B9,'Project Timeline'!$F$5:$F$89,"<="&C9)) | M9: =IF(J9="","",SUMIFS('Claude Usage Daily'!$O$5:$O$115,'Claude Usage Daily'!$A$5:$A$115,">="&B9,'Claude Usage Daily'!$A$5:$A$115,"<="&C9)) | O9: =IF(J9="","",IF(N9="",J9*'Overall'!$G$29/DeliveryDays,N9)+J9*('Overall'!$D$43+'Overall'!$D$44+'Overall'!$D$45+'Overall'!$D$46)/DeliveryDays+N(M9)) | P9: =IF(O9="","",O9-N(I9))
A10: 6 | B10: =IF(OR(D10="",ProjectStart=""),"",WORKDAY(ProjectStart,(6-1)*SprintDays)) | C10: =IF(B10="","",WORKDAY(B10,SprintDays-1)) | D10: =IF(OR(MIN(SprintDays,MAX(0,DeliveryDays-(6-1)*SprintDays))>0,AND(ProjectStart<>"",LastActual<>"",WORKDAY(ProjectStart,(6-1)*SprintDays)<=N(LastActual))),MIN(SprintDays,MAX(0,DeliveryDays-(6-1)*SprintDays)),"") | E10: 5.1 Region-2 AKS from the same Terraform module 5.2 Front Door origins, health probes and Front Door-only ingress 5.3 SQL failover group behind a Terraform flag 5.4 Grafana requests-per-second by region 5.5 Regional failover drill and runbook | F10: =IF(D10="","",D10*'Overall'!$G$29/DeliveryDays) | G10: =IF(D10="","",D10*('Overall'!$D$43+'Overall'!$D$44+'Overall'!$D$45+'Overall'!$D$46)/DeliveryDays) | I10: =IF(D10="","",F10+G10+N(H10)) | J10: =IF(OR(B10="",LastActual="",B10>N(LastActual)),"",NETWORKDAYS(B10,MIN(C10,LastActual))) | K10: =IF(J10="","",COUNTIFS('Project Timeline'!$A$5:$A$89,"story",'Project Timeline'!$F$5:$F$89,">="&B10,'Project Timeline'!$F$5:$F$89,"<="&C10)) | M10: =IF(J10="","",SUMIFS('Claude Usage Daily'!$O$5:$O$115,'Claude Usage Daily'!$A$5:$A$115,">="&B10,'Claude Usage Daily'!$A$5:$A$115,"<="&C10)) | O10: =IF(J10="","",IF(N10="",J10*'Overall'!$G$29/DeliveryDays,N10)+J10*('Overall'!$D$43+'Overall'!$D$44+'Overall'!$D$45+'Overall'!$D$46)/DeliveryDays+N(M10)) | P10: =IF(O10="","",O10-N(I10))
A11: 7 | B11: =IF(OR(D11="",ProjectStart=""),"",WORKDAY(ProjectStart,(7-1)*SprintDays)) | C11: =IF(B11="","",WORKDAY(B11,SprintDays-1)) | D11: =IF(OR(MIN(SprintDays,MAX(0,DeliveryDays-(7-1)*SprintDays))>0,AND(ProjectStart<>"",LastActual<>"",WORKDAY(ProjectStart,(7-1)*SprintDays)<=N(LastActual))),MIN(SprintDays,MAX(0,DeliveryDays-(7-1)*SprintDays)),"") | E11: 6.1 Security controls evidence pack for the CISO review 6.2 PDPA data-protection assessment and penetration test remediation 6.3 UAT with Group Treasury and business sign-off | F11: =IF(D11="","",D11*'Overall'!$G$29/DeliveryDays) | G11: =IF(D11="","",D11*('Overall'!$D$43+'Overall'!$D$44+'Overall'!$D$45+'Overall'!$D$46)/DeliveryDays) | I11: =IF(D11="","",F11+G11+N(H11)) | J11: =IF(OR(B11="",LastActual="",B11>N(LastActual)),"",NETWORKDAYS(B11,MIN(C11,LastActual))) | K11: =IF(J11="","",COUNTIFS('Project Timeline'!$A$5:$A$89,"story",'Project Timeline'!$F$5:$F$89,">="&B11,'Project Timeline'!$F$5:$F$89,"<="&C11)) | M11: =IF(J11="","",SUMIFS('Claude Usage Daily'!$O$5:$O$115,'Claude Usage Daily'!$A$5:$A$115,">="&B11,'Claude Usage Daily'!$A$5:$A$115,"<="&C11)) | O11: =IF(J11="","",IF(N11="",J11*'Overall'!$G$29/DeliveryDays,N11)+J11*('Overall'!$D$43+'Overall'!$D$44+'Overall'!$D$45+'Overall'!$D$46)/DeliveryDays+N(M11)) | P11: =IF(O11="","",O11-N(I11))
A12: 8 | B12: =IF(OR(D12="",ProjectStart=""),"",WORKDAY(ProjectStart,(8-1)*SprintDays)) | C12: =IF(B12="","",WORKDAY(B12,SprintDays-1)) | D12: =IF(OR(MIN(SprintDays,MAX(0,DeliveryDays-(8-1)*SprintDays))>0,AND(ProjectStart<>"",LastActual<>"",WORKDAY(ProjectStart,(8-1)*SprintDays)<=N(LastActual))),MIN(SprintDays,MAX(0,DeliveryDays-(8-1)*SprintDays)),"") | E12: 6.4 CAB approval, production cut-over and hypercare | F12: =IF(D12="","",D12*'Overall'!$G$29/DeliveryDays) | G12: =IF(D12="","",D12*('Overall'!$D$43+'Overall'!$D$44+'Overall'!$D$45+'Overall'!$D$46)/DeliveryDays) | I12: =IF(D12="","",F12+G12+N(H12)) | J12: =IF(OR(B12="",LastActual="",B12>N(LastActual)),"",NETWORKDAYS(B12,MIN(C12,LastActual))) | K12: =IF(J12="","",COUNTIFS('Project Timeline'!$A$5:$A$89,"story",'Project Timeline'!$F$5:$F$89,">="&B12,'Project Timeline'!$F$5:$F$89,"<="&C12)) | M12: =IF(J12="","",SUMIFS('Claude Usage Daily'!$O$5:$O$115,'Claude Usage Daily'!$A$5:$A$115,">="&B12,'Claude Usage Daily'!$A$5:$A$115,"<="&C12)) | O12: =IF(J12="","",IF(N12="",J12*'Overall'!$G$29/DeliveryDays,N12)+J12*('Overall'!$D$43+'Overall'!$D$44+'Overall'!$D$45+'Overall'!$D$46)/DeliveryDays+N(M12)) | P12: =IF(O12="","",O12-N(I12))
A13: 9 | B13: =IF(OR(D13="",ProjectStart=""),"",WORKDAY(ProjectStart,(9-1)*SprintDays)) | C13: =IF(B13="","",WORKDAY(B13,SprintDays-1)) | D13: =IF(OR(MIN(SprintDays,MAX(0,DeliveryDays-(9-1)*SprintDays))>0,AND(ProjectStart<>"",LastActual<>"",WORKDAY(ProjectStart,(9-1)*SprintDays)<=N(LastActual))),MIN(SprintDays,MAX(0,DeliveryDays-(9-1)*SprintDays)),"") | F13: =IF(D13="","",D13*'Overall'!$G$29/DeliveryDays) | G13: =IF(D13="","",D13*('Overall'!$D$43+'Overall'!$D$44+'Overall'!$D$45+'Overall'!$D$46)/DeliveryDays) | I13: =IF(D13="","",F13+G13+N(H13)) | J13: =IF(OR(B13="",LastActual="",B13>N(LastActual)),"",NETWORKDAYS(B13,MIN(C13,LastActual))) | K13: =IF(J13="","",COUNTIFS('Project Timeline'!$A$5:$A$89,"story",'Project Timeline'!$F$5:$F$89,">="&B13,'Project Timeline'!$F$5:$F$89,"<="&C13)) | M13: =IF(J13="","",SUMIFS('Claude Usage Daily'!$O$5:$O$115,'Claude Usage Daily'!$A$5:$A$115,">="&B13,'Claude Usage Daily'!$A$5:$A$115,"<="&C13)) | O13: =IF(J13="","",IF(N13="",J13*'Overall'!$G$29/DeliveryDays,N13)+J13*('Overall'!$D$43+'Overall'!$D$44+'Overall'!$D$45+'Overall'!$D$46)/DeliveryDays+N(M13)) | P13: =IF(O13="","",O13-N(I13))
A14: 10 | B14: =IF(OR(D14="",ProjectStart=""),"",WORKDAY(ProjectStart,(10-1)*SprintDays)) | C14: =IF(B14="","",WORKDAY(B14,SprintDays-1)) | D14: =IF(OR(MIN(SprintDays,MAX(0,DeliveryDays-(10-1)*SprintDays))>0,AND(ProjectStart<>"",LastActual<>"",WORKDAY(ProjectStart,(10-1)*SprintDays)<=N(LastActual))),MIN(SprintDays,MAX(0,DeliveryDays-(10-1)*SprintDays)),"") | F14: =IF(D14="","",D14*'Overall'!$G$29/DeliveryDays) | G14: =IF(D14="","",D14*('Overall'!$D$43+'Overall'!$D$44+'Overall'!$D$45+'Overall'!$D$46)/DeliveryDays) | I14: =IF(D14="","",F14+G14+N(H14)) | J14: =IF(OR(B14="",LastActual="",B14>N(LastActual)),"",NETWORKDAYS(B14,MIN(C14,LastActual))) | K14: =IF(J14="","",COUNTIFS('Project Timeline'!$A$5:$A$89,"story",'Project Timeline'!$F$5:$F$89,">="&B14,'Project Timeline'!$F$5:$F$89,"<="&C14)) | M14: =IF(J14="","",SUMIFS('Claude Usage Daily'!$O$5:$O$115,'Claude Usage Daily'!$A$5:$A$115,">="&B14,'Claude Usage Daily'!$A$5:$A$115,"<="&C14)) | O14: =IF(J14="","",IF(N14="",J14*'Overall'!$G$29/DeliveryDays,N14)+J14*('Overall'!$D$43+'Overall'!$D$44+'Overall'!$D$45+'Overall'!$D$46)/DeliveryDays+N(M14)) | P14: =IF(O14="","",O14-N(I14))
A15: 11 | B15: =IF(OR(D15="",ProjectStart=""),"",WORKDAY(ProjectStart,(11-1)*SprintDays)) | C15: =IF(B15="","",WORKDAY(B15,SprintDays-1)) | D15: =IF(OR(MIN(SprintDays,MAX(0,DeliveryDays-(11-1)*SprintDays))>0,AND(ProjectStart<>"",LastActual<>"",WORKDAY(ProjectStart,(11-1)*SprintDays)<=N(LastActual))),MIN(SprintDays,MAX(0,DeliveryDays-(11-1)*SprintDays)),"") | F15: =IF(D15="","",D15*'Overall'!$G$29/DeliveryDays) | G15: =IF(D15="","",D15*('Overall'!$D$43+'Overall'!$D$44+'Overall'!$D$45+'Overall'!$D$46)/DeliveryDays) | I15: =IF(D15="","",F15+G15+N(H15)) | J15: =IF(OR(B15="",LastActual="",B15>N(LastActual)),"",NETWORKDAYS(B15,MIN(C15,LastActual))) | K15: =IF(J15="","",COUNTIFS('Project Timeline'!$A$5:$A$89,"story",'Project Timeline'!$F$5:$F$89,">="&B15,'Project Timeline'!$F$5:$F$89,"<="&C15)) | M15: =IF(J15="","",SUMIFS('Claude Usage Daily'!$O$5:$O$115,'Claude Usage Daily'!$A$5:$A$115,">="&B15,'Claude Usage Daily'!$A$5:$A$115,"<="&C15)) | O15: =IF(J15="","",IF(N15="",J15*'Overall'!$G$29/DeliveryDays,N15)+J15*('Overall'!$D$43+'Overall'!$D$44+'Overall'!$D$45+'Overall'!$D$46)/DeliveryDays+N(M15)) | P15: =IF(O15="","",O15-N(I15))
A16: Total | D16: =SUM(D5:D15) | F16: =SUM(F5:F15) | G16: =SUM(G5:G15) | H16: =SUM(H5:H15) | I16: =SUM(I5:I15) | J16: =SUM(J5:J15) | K16: =SUM(K5:K15) | M16: =SUM(M5:M15) | N16: =SUM(N5:N15) | O16: =SUM(O5:O15) | P16: =SUM(P5:P15)

Sheet Phase Budgets
A1: Phase budgets: Claude API budget and actual per planning phase
A2: In USD, at Claude API list prices. The budget each planning phase may spend (test design, governance, diagrams, course corrections ...), set once the epics and sprint plan are done; the epics and sprints carry their own budgets on their sheets. Actual: the phase's Claude cost from the ledger (Claude Usage Detail) once the close-out sheets are in. A control figure: not added to any total. Blue cells are inputs; name a phase as the token ledger does.
A4: Phase | B4: Claude API budget (USD) | C4: Claude API actual (USD) | D4: Variance (USD) | E4: Variance % | F4: Cited from
A5: brainstorming | B5: 15 | C5: =IF(A5="","",SUMIFS('Claude Usage Detail'!$P$5:$P$43,'Claude Usage Detail'!$B$5:$B$43,A5)) | D5: =IF(OR(A5="",C5=""),"",C5-N(B5)) | E5: =IF(OR(D5="",N(B5)=0),"",C5/B5-1) | F5: assumption: owner's Claude API budget per phase; synthetic portfolio figure, owner request 2026-09-30
A6: spec | B6: 30 | C6: =IF(A6="","",SUMIFS('Claude Usage Detail'!$P$5:$P$43,'Claude Usage Detail'!$B$5:$B$43,A6)) | D6: =IF(OR(A6="",C6=""),"",C6-N(B6)) | E6: =IF(OR(D6="",N(B6)=0),"",C6/B6-1) | F6: assumption: owner's Claude API budget per phase; synthetic portfolio figure, owner request 2026-09-30
A7: architecture | B7: 55 | C7: =IF(A7="","",SUMIFS('Claude Usage Detail'!$P$5:$P$43,'Claude Usage Detail'!$B$5:$B$43,A7)) | D7: =IF(OR(A7="",C7=""),"",C7-N(B7)) | E7: =IF(OR(D7="",N(B7)=0),"",C7/B7-1) | F7: assumption: owner's Claude API budget per phase; synthetic portfolio figure, owner request 2026-09-30
A8: UX design | B8: 45 | C8: =IF(A8="","",SUMIFS('Claude Usage Detail'!$P$5:$P$43,'Claude Usage Detail'!$B$5:$B$43,A8)) | D8: =IF(OR(A8="",C8=""),"",C8-N(B8)) | E8: =IF(OR(D8="",N(B8)=0),"",C8/B8-1) | F8: assumption: owner's Claude API budget per phase; synthetic portfolio figure, owner request 2026-09-30
A9: governance (Jules) | B9: 20 | C9: =IF(A9="","",SUMIFS('Claude Usage Detail'!$P$5:$P$43,'Claude Usage Detail'!$B$5:$B$43,A9)) | D9: =IF(OR(A9="",C9=""),"",C9-N(B9)) | E9: =IF(OR(D9="",N(B9)=0),"",C9/B9-1) | F9: assumption: owner's Claude API budget per phase; synthetic portfolio figure, owner request 2026-09-30
A10: architecture docs (Da Vinci) | B10: 25 | C10: =IF(A10="","",SUMIFS('Claude Usage Detail'!$P$5:$P$43,'Claude Usage Detail'!$B$5:$B$43,A10)) | D10: =IF(OR(A10="",C10=""),"",C10-N(B10)) | E10: =IF(OR(D10="",N(B10)=0),"",C10/B10-1) | F10: assumption: owner's Claude API budget per phase; synthetic portfolio figure, owner request 2026-09-30
A11: epics & stories | B11: 35 | C11: =IF(A11="","",SUMIFS('Claude Usage Detail'!$P$5:$P$43,'Claude Usage Detail'!$B$5:$B$43,A11)) | D11: =IF(OR(A11="",C11=""),"",C11-N(B11)) | E11: =IF(OR(D11="",N(B11)=0),"",C11/B11-1) | F11: assumption: owner's Claude API budget per phase; synthetic portfolio figure, owner request 2026-09-30
A12: merges, promotions & deploys | B12: 30 | C12: =IF(A12="","",SUMIFS('Claude Usage Detail'!$P$5:$P$43,'Claude Usage Detail'!$B$5:$B$43,A12)) | D12: =IF(OR(A12="",C12=""),"",C12-N(B12)) | E12: =IF(OR(D12="",N(B12)=0),"",C12/B12-1) | F12: assumption: owner's Claude API budget per phase; synthetic portfolio figure, owner request 2026-09-30
C13: =IF(A13="","",SUMIFS('Claude Usage Detail'!$P$5:$P$43,'Claude Usage Detail'!$B$5:$B$43,A13)) | D13: =IF(OR(A13="",C13=""),"",C13-N(B13)) | E13: =IF(OR(D13="",N(B13)=0),"",C13/B13-1)
C14: =IF(A14="","",SUMIFS('Claude Usage Detail'!$P$5:$P$43,'Claude Usage Detail'!$B$5:$B$43,A14)) | D14: =IF(OR(A14="",C14=""),"",C14-N(B14)) | E14: =IF(OR(D14="",N(B14)=0),"",C14/B14-1)
C15: =IF(A15="","",SUMIFS('Claude Usage Detail'!$P$5:$P$43,'Claude Usage Detail'!$B$5:$B$43,A15)) | D15: =IF(OR(A15="",C15=""),"",C15-N(B15)) | E15: =IF(OR(D15="",N(B15)=0),"",C15/B15-1)
A16: Total | B16: =SUM(B5:B15) | C16: =SUM(C5:C15) | D16: =SUM(D5:D15)

Sheet Revenue
A1: Revenue
A2: Revenue the solution earns, per year after go-live, in USD, from the owner or the business case; each stream cites its source. Years past the horizon are ignored. Blue cells are inputs.
A4: # | B4: Stream | C4: Basis | D4: Year 1 | E4: Year 2 | F4: Year 3 | G4: Year 4 | H4: Year 5 | I4: Cited from | J4: Note
A8: Total | D8: =SUM(D5:D7) | E8: =SUM(E5:E7) | F8: =SUM(F5:F7) | G8: =SUM(G5:G7) | H8: =SUM(H5:H7)

Sheet Rate Card
A1: Employee rate card
A2: Day rates in USD. Source: owner, 2026-09-28 (blended average day rate per person); updated 2026-09-30. Blue cells are inputs; the team and support tables look roles up here.
A4: Role | B4: Day rate (USD) | C4: Note
A5: Team member (blended) | B5: 800 | C5: blended average across delivery roles
A6: Delivery lead | B6: 800 | C6: blended rate
A7: Solution architect | B7: 800 | C7: blended rate
A8: Full-stack developer | B8: 800 | C8: blended rate
A9: Mobile developer | B9: 800 | C9: blended rate
A10: Cloud / DevOps engineer | B10: 800 | C10: blended rate
A11: Data engineer | B11: 800 | C11: blended rate
A12: QA engineer | B12: 800 | C12: blended rate
A13: UX designer | B13: 800 | C13: blended rate
A14: Support engineer | B14: 800 | C14: blended rate, run support (OPEX)

Sheet Other Costs
A1: Other one-off costs
A2: Licences, tests, training and other one-off costs of the build, outside the environments and the team, in USD.
A4: # | B4: Item | C4: Amount (USD) | D4: Cited from | E4: Note | F4: Epic
A5: 1 | B5: Penetration test (external CREST tester) | C5: 18000 | D5: assumption: pre-go-live pen test required by Sentral's Group Security; synthetic portfolio figure, owner request 2026-09-30 | F5: 6
A6: 2 | B6: PDPA data-protection impact assessment | C6: 7500 | D6: assumption: external privacy counsel for PDPA 2010 and cross-border transfer; synthetic portfolio figure, owner request 2026-09-30 | F6: 6
A10: Total | C10: =SUM(C5:C9)

Sheet Run Costs
A1: Recurring run costs (OPEX)
A2: Yearly costs of running the solution outside the cloud environments and the support team: support contracts, licences, subscriptions. In USD per year; the Multi-Year sheet escalates them by the yearly increase.
A4: # | B4: Item | C4: Annual cost (USD) | D4: Cited from | E4: Note
A5: 1 | B5: Annual penetration test | C5: 15000 | D5: assumption: Sentral Group Security policy, yearly retest; synthetic portfolio figure, owner request 2026-09-30
A9: Total | C9: =SUM(C5:C8)

Sheet Dev
A1: Dev environment
A2: Azure retail list prices (pay-as-you-go) in westus3, USD, fetched 2026-09-30. Daily cost is the monthly cost spread over the year (x 12 / 365). Blue cells are inputs.
A4: # | B4: Component | C4: Azure service | D4: SKU / tier | E4: Unit | F4: Unit price (USD) | G4: Quantity | H4: Usage per month | I4: Monthly cost (USD) | J4: Daily cost (USD) | K4: Annual cost (USD) | L4: Cited from | M4: Price source | N4: Note | O4: Environment
A5: 1 | B5: AKS system node | C5: Virtual Machines | D5: Standard_D4s_v5 | E5: 1 Hour | F5: 0.192 | G5: 1 | H5: 220 | I5: =F5*G5*H5*FxRate | J5: =I5*12/365 | K5: =I5*12 | L5: _bmad-output/specs/spec-corporate-portal-poc/stack.md AKS with Node Auto Provisioning | M5: Azure Retail Prices API, Virtual Machines Dsv5 Series / D4s v5, westus3, USD per 1 Hour, meterId a7d0753e-6fcd-5b61-8b6e-4727c10691a1, fetched 2026-09-30 | N5: One regular system node; cluster stopped nights and weekends (~220 h/month), per cost-budget.md | O5: Dev
A6: 2 | B6: AKS spot service nodes | C6: Virtual Machines | D6: Standard_D4s_v5 Spot | E6: 1 Hour | F6: 0.035597 | G6: 2 | H6: 220 | I6: =F6*G6*H6*FxRate | J6: =I6*12/365 | K6: =I6*12 | L6: _bmad-output/specs/spec-corporate-portal-poc/stack.md spot nodes for services during development | M6: Azure Retail Prices API, Virtual Machines Dsv5 Series / D4s v5 Spot, westus3, USD per 1 Hour, meterId 6e242d37-4313-55fe-aa86-eb489f126a81, fetched 2026-09-30 | N6: Karpenter spot nodes, stopped with the cluster | O6: Dev
A7: 3 | B7: Azure SQL ledger (Basic) | C7: SQL Database | D7: Basic 5 DTU | E7: 1/Day | F7: 0.161 | G7: 1 | H7: 30.4167 | I7: =F7*G7*H7*FxRate | J7: =I7*12/365 | K7: =I7*12 | L7: _bmad-output/specs/spec-corporate-portal-poc/stack.md Basic tier during development | M7: Azure Retail Prices API, SQL Database Single Basic / B DTU, westus3, USD per 1/Day, meterId cae64797-9ecf-4906-b517-6238c80c045f, fetched 2026-09-30 | O7: Dev
A8: 4 | B8: Event Hubs namespace | C8: Event Hubs | D8: Standard, 1 TU | E8: 1 Hour | F8: 0.03 | G8: 1 | H8: =HoursPerMonth | I8: =F8*G8*H8*FxRate | J8: =I8*12/365 | K8: =I8*12 | L8: _bmad-output/specs/spec-corporate-portal-poc/stack.md Event Hubs Standard (1 TU, 7-day retention) | M8: Azure Retail Prices API, Event Hubs / Standard Throughput Unit, westus3, USD per 1 Hour, meterId 62d94a65-9300-48a6-8c15-0e70fc41eb44, fetched 2026-09-30 | O8: Dev
A9: 5 | B9: Databricks jobs compute (DBU) | C9: Azure Databricks | D9: Premium Jobs Compute | E9: 1 Hour | F9: 0.3 | G9: 1 | H9: 40 | I9: =F9*G9*H9*FxRate | J9: =I9*12/365 | K9: =I9*12 | L9: _bmad-output/specs/spec-corporate-portal-poc/stack.md Databricks Premium: | M9: Azure Retail Prices API, Azure Databricks / Premium Jobs Compute DBU, westus3, USD per 1 Hour, meterId 8ee07b23-82ae-430e-a417-a050463ff4ee, fetched 2026-09-30 | N9: assumption: single-node D4s_v5 at 1 DBU/h, ~40 h a month of on-demand runs (cluster policy auto-stops after 10 min); synthetic portfolio figure, owner request 2026-09-30 | O9: Dev
A10: 6 | B10: Databricks cluster VM | C10: Virtual Machines | D10: Standard_D4s_v5 | E10: 1 Hour | F10: 0.192 | G10: 1 | H10: 40 | I10: =F10*G10*H10*FxRate | J10: =I10*12/365 | K10: =I10*12 | L10: _bmad-output/specs/spec-corporate-portal-poc/stack.md Cluster policy: single node, smallest VM, auto-stop after 10 minutes | M10: Azure Retail Prices API, Virtual Machines Dsv5 Series / D4s v5, westus3, USD per 1 Hour, meterId a7d0753e-6fcd-5b61-8b6e-4727c10691a1, fetched 2026-09-30 | N10: same ~40 h a month as the DBUs | O10: Dev
A11: 7 | B11: Data lake (ADLS Gen2) | C11: Storage | D11: Hot LRS, hierarchical namespace | E11: 1 GB/Month | F11: 0.0184 | G11: 100 | H11: 1 | I11: =F11*G11*H11*FxRate | J11: =I11*12/365 | K11: =I11*12 | L11: _bmad-output/specs/spec-corporate-portal-poc/stack.md Medallion: ADLS Gen2 | M11: Azure Retail Prices API, Azure Data Lake Storage Gen2 Hierarchical Namespace / Hot LRS Data Stored, westus3, USD per 1 GB/Month, meterId 08da9c52-d07e-566a-8952-89c0e93464b6, fetched 2026-09-30 | N11: assumption: 100 GB of synthetic bronze/silver/gold data; synthetic portfolio figure, owner request 2026-09-30 | O11: Dev
A12: 8 | B12: Key Vault operations | C12: Key Vault | D12: Standard | E12: 10K | F12: 0.03 | G12: 10 | H12: 1 | I12: =F12*G12*H12*FxRate | J12: =I12*12/365 | K12: =I12*12 | L12: _bmad-output/specs/spec-corporate-portal-poc/stack.md HashiCorp Vault for app secrets | M12: Azure Retail Prices API, Key Vault / Operations (Standard), westus3, USD per 10K, meterId 0f824807-2376-435c-95c9-f992b67a07b0, fetched 2026-09-30 | N12: assumption: 100K operations a month (Vault auto-unseal and root credentials); synthetic portfolio figure, owner request 2026-09-30 | O12: Dev
A13: 9 | B13: Private endpoints | C13: Virtual Network | D13: Standard Private Endpoint | E13: 1 Hour | F13: 0.01 | G13: 4 | H13: =HoursPerMonth | I13: =F13*G13*H13*FxRate | J13: =I13*12/365 | K13: =I13*12 | L13: _bmad-output/specs/spec-corporate-portal-poc/stack.md Private endpoints: ADLS, SQL, Key Vault and Event Hubs | M13: Azure Retail Prices API, Virtual Network Private Link / Standard Private Endpoint, Global, USD per 1 Hour, meterId e6ab7238-e433-4fe0-a2b2-2b2564df2cdb, fetched 2026-09-30 | N13: 4 endpoints (lake, SQL, Key Vault, Event Hubs per region) | O13: Dev
A14: 10 | B14: Private endpoint data processed | C14: Virtual Network | D14: Private Link data processed | E14: 1 GB | F14: 0.01 | G14: 1 | H14: 20 | I14: =F14*G14*H14*FxRate | J14: =I14*12/365 | K14: =I14*12 | L14: _bmad-output/specs/spec-corporate-portal-poc/stack.md Private endpoints: ADLS, SQL, Key Vault and Event Hubs | M14: Azure Retail Prices API, Virtual Network Private Link / Standard Data Processed - Ingress, Global, USD per 1 GB, meterId 10caa28b-6479-4852-9eb7-610870cb6417, fetched 2026-09-30 | N14: assumption: 20 GB a month through the private endpoints; synthetic portfolio figure, owner request 2026-09-30 | O14: Dev
A15: 11 | B15: Private DNS zones | C15: Azure DNS | D15: Private Zone | E15: 1/Month | F15: 0.5 | G15: 4 | H15: 1 | I15: =F15*G15*H15*FxRate | J15: =I15*12/365 | K15: =I15*12 | L15: _bmad-output/specs/spec-corporate-portal-poc/stack.md Private endpoints: ADLS, SQL, Key Vault and Event Hubs | M15: Azure Retail Prices API, Azure DNS / Private Zone, Zone 1, USD per 1, meterId 0b608a26-f611-4232-8192-ce81b6b57194, fetched 2026-09-30 | N15: one zone per private-endpoint service | O15: Dev
A16: 12 | B16: NAT gateway (Databricks egress) | C16: NAT Gateway | D16: Standard | E16: 1 Hour | F16: 0.045 | G16: 1 | H16: =HoursPerMonth | I16: =F16*G16*H16*FxRate | J16: =I16*12/365 | K16: =I16*12 | L16: _bmad-output/specs/spec-corporate-portal-poc/stack.md VNet-injected with a NAT gateway | M16: Azure Retail Prices API, NAT Gateway / Standard Gateway, Global, USD per 1 Hour, meterId ae30040a-67f5-485b-b0f4-a6ef50504d9c, fetched 2026-09-30 | O16: Dev
A17: 13 | B17: NAT gateway data processed | C17: NAT Gateway | D17: Standard data processed | E17: 1 GB | F17: 0.045 | G17: 1 | H17: 20 | I17: =F17*G17*H17*FxRate | J17: =I17*12/365 | K17: =I17*12 | L17: _bmad-output/specs/spec-corporate-portal-poc/stack.md VNet-injected with a NAT gateway | M17: Azure Retail Prices API, NAT Gateway / Standard Data Processed, Global, USD per 1 GB, meterId d32b6352-b66b-4c4c-8f21-60e94058e04d, fetched 2026-09-30 | N17: assumption: 20 GB of Databricks egress a month; synthetic portfolio figure, owner request 2026-09-30 | O17: Dev
A18: 14 | B18: Kong ingress load balancer | C18: Load Balancer | D18: Standard | E18: 1 Hour | F18: 0.025 | G18: 1 | H18: =HoursPerMonth | I18: =F18*G18*H18*FxRate | J18: =I18*12/365 | K18: =I18*12 | L18: _bmad-output/specs/spec-corporate-portal-poc/stack.md Kong OSS as the API gateway (ingress) | M18: Azure Retail Prices API, Load Balancer / Standard Included LB Rules and Outbound Rules, Global, USD per 1 Hour, meterId 27827eb0-7f60-4928-940b-f5fe15e7a4cb, fetched 2026-09-30 | O18: Dev
A19: 15 | B19: Ingress public IPs | C19: Virtual Network | D19: Standard IPv4 static | E19: 1 Hour | F19: 0.005 | G19: 1 | H19: =HoursPerMonth | I19: =F19*G19*H19*FxRate | J19: =I19*12/365 | K19: =I19*12 | L19: _bmad-output/specs/spec-corporate-portal-poc/stack.md Kong OSS as the API gateway (ingress) | M19: Azure Retail Prices API, IP Addresses / Standard IPv4 Static Public IP, westus3, USD per 1 Hour, meterId 9c150bf9-2bad-430e-a53c-c213804f49ef, fetched 2026-09-30 | O19: Dev
I20: =IF(F20="","",F20*G20*H20*FxRate) | J20: =IF(I20="","",I20*12/365) | K20: =IF(I20="","",I20*12) | O20: Dev
I21: =IF(F21="","",F21*G21*H21*FxRate) | J21: =IF(I21="","",I21*12/365) | K21: =IF(I21="","",I21*12) | O21: Dev
I22: =IF(F22="","",F22*G22*H22*FxRate) | J22: =IF(I22="","",I22*12/365) | K22: =IF(I22="","",I22*12) | O22: Dev
A23: Total | I23: =SUM(I5:I22) | J23: =SUM(J5:J22) | K23: =SUM(K5:K22)

Sheet Test
A1: Test environment
A2: Azure retail list prices (pay-as-you-go) in westus3, USD, fetched 2026-09-30. Daily cost is the monthly cost spread over the year (x 12 / 365). Blue cells are inputs.
A4: # | B4: Component | C4: Azure service | D4: SKU / tier | E4: Unit | F4: Unit price (USD) | G4: Quantity | H4: Usage per month | I4: Monthly cost (USD) | J4: Daily cost (USD) | K4: Annual cost (USD) | L4: Cited from | M4: Price source | N4: Note | O4: Environment
A5: 1 | B5: AKS nodes | C5: Virtual Machines | D5: Standard_D4s_v5 | E5: 1 Hour | F5: 0.192 | G5: 2 | H5: 260 | I5: =F5*G5*H5*FxRate | J5: =I5*12/365 | K5: =I5*12 | L5: _bmad-output/specs/spec-corporate-portal-poc/stack.md AKS with Node Auto Provisioning | M5: Azure Retail Prices API, Virtual Machines Dsv5 Series / D4s v5, westus3, USD per 1 Hour, meterId a7d0753e-6fcd-5b61-8b6e-4727c10691a1, fetched 2026-09-30 | N5: assumption: 2 regular nodes, weekdays 12 h a day (~260 h/month); stopped otherwise; synthetic portfolio figure, owner request 2026-09-30 | O5: Test
A6: 2 | B6: Azure SQL ledger (S1) | C6: SQL Database | D6: Standard S1 20 DTU | E6: 1/Day | F6: 0.9677 | G6: 1 | H6: 30.4167 | I6: =F6*G6*H6*FxRate | J6: =I6*12/365 | K6: =I6*12 | L6: _bmad-output/specs/spec-corporate-portal-poc/stack.md Operational ledger, including payment approval state and an outbox table | M6: Azure Retail Prices API, SQL Database Single Standard / S1 DTUs, westus3, USD per 1/Day, meterId 54c6bbf3-322b-406d-8411-101bc4b9443a, fetched 2026-09-30 | N6: assumption: S1 for integration and regression runs; synthetic portfolio figure, owner request 2026-09-30 | O6: Test
A7: 3 | B7: Event Hubs namespace | C7: Event Hubs | D7: Standard, 1 TU | E7: 1 Hour | F7: 0.03 | G7: 1 | H7: =HoursPerMonth | I7: =F7*G7*H7*FxRate | J7: =I7*12/365 | K7: =I7*12 | L7: _bmad-output/specs/spec-corporate-portal-poc/stack.md Event Hubs Standard (1 TU, 7-day retention) | M7: Azure Retail Prices API, Event Hubs / Standard Throughput Unit, westus3, USD per 1 Hour, meterId 62d94a65-9300-48a6-8c15-0e70fc41eb44, fetched 2026-09-30 | O7: Test
A8: 4 | B8: Databricks jobs compute (DBU) | C8: Azure Databricks | D8: Premium Jobs Compute | E8: 1 Hour | F8: 0.3 | G8: 1 | H8: 60 | I8: =F8*G8*H8*FxRate | J8: =I8*12/365 | K8: =I8*12 | L8: _bmad-output/specs/spec-corporate-portal-poc/stack.md Databricks Premium: | M8: Azure Retail Prices API, Azure Databricks / Premium Jobs Compute DBU, westus3, USD per 1 Hour, meterId 8ee07b23-82ae-430e-a417-a050463ff4ee, fetched 2026-09-30 | N8: assumption: single node at 1 DBU/h, ~60 h a month of test runs; synthetic portfolio figure, owner request 2026-09-30 | O8: Test
A9: 5 | B9: Databricks cluster VM | C9: Virtual Machines | D9: Standard_D4s_v5 | E9: 1 Hour | F9: 0.192 | G9: 1 | H9: 60 | I9: =F9*G9*H9*FxRate | J9: =I9*12/365 | K9: =I9*12 | L9: _bmad-output/specs/spec-corporate-portal-poc/stack.md Databricks Premium: | M9: Azure Retail Prices API, Virtual Machines Dsv5 Series / D4s v5, westus3, USD per 1 Hour, meterId a7d0753e-6fcd-5b61-8b6e-4727c10691a1, fetched 2026-09-30 | N9: same ~60 h a month as the DBUs | O9: Test
A10: 6 | B10: Data lake (ADLS Gen2) | C10: Storage | D10: Hot LRS, hierarchical namespace | E10: 1 GB/Month | F10: 0.0184 | G10: 200 | H10: 1 | I10: =F10*G10*H10*FxRate | J10: =I10*12/365 | K10: =I10*12 | L10: _bmad-output/specs/spec-corporate-portal-poc/stack.md Medallion: ADLS Gen2 | M10: Azure Retail Prices API, Azure Data Lake Storage Gen2 Hierarchical Namespace / Hot LRS Data Stored, westus3, USD per 1 GB/Month, meterId 08da9c52-d07e-566a-8952-89c0e93464b6, fetched 2026-09-30 | N10: assumption: 200 GB of synthetic test data; synthetic portfolio figure, owner request 2026-09-30 | O10: Test
A11: 7 | B11: Key Vault operations | C11: Key Vault | D11: Standard | E11: 10K | F11: 0.03 | G11: 20 | H11: 1 | I11: =F11*G11*H11*FxRate | J11: =I11*12/365 | K11: =I11*12 | L11: _bmad-output/specs/spec-corporate-portal-poc/stack.md HashiCorp Vault for app secrets | M11: Azure Retail Prices API, Key Vault / Operations (Standard), westus3, USD per 10K, meterId 0f824807-2376-435c-95c9-f992b67a07b0, fetched 2026-09-30 | N11: assumption: 200K operations a month; synthetic portfolio figure, owner request 2026-09-30 | O11: Test
A12: 8 | B12: Private endpoints | C12: Virtual Network | D12: Standard Private Endpoint | E12: 1 Hour | F12: 0.01 | G12: 4 | H12: =HoursPerMonth | I12: =F12*G12*H12*FxRate | J12: =I12*12/365 | K12: =I12*12 | L12: _bmad-output/specs/spec-corporate-portal-poc/stack.md Private endpoints: ADLS, SQL, Key Vault and Event Hubs | M12: Azure Retail Prices API, Virtual Network Private Link / Standard Private Endpoint, Global, USD per 1 Hour, meterId e6ab7238-e433-4fe0-a2b2-2b2564df2cdb, fetched 2026-09-30 | N12: 4 endpoints (lake, SQL, Key Vault, Event Hubs per region) | O12: Test
A13: 9 | B13: Private endpoint data processed | C13: Virtual Network | D13: Private Link data processed | E13: 1 GB | F13: 0.01 | G13: 1 | H13: 40 | I13: =F13*G13*H13*FxRate | J13: =I13*12/365 | K13: =I13*12 | L13: _bmad-output/specs/spec-corporate-portal-poc/stack.md Private endpoints: ADLS, SQL, Key Vault and Event Hubs | M13: Azure Retail Prices API, Virtual Network Private Link / Standard Data Processed - Ingress, Global, USD per 1 GB, meterId 10caa28b-6479-4852-9eb7-610870cb6417, fetched 2026-09-30 | N13: assumption: 40 GB a month through the private endpoints; synthetic portfolio figure, owner request 2026-09-30 | O13: Test
A14: 10 | B14: Private DNS zones | C14: Azure DNS | D14: Private Zone | E14: 1/Month | F14: 0.5 | G14: 4 | H14: 1 | I14: =F14*G14*H14*FxRate | J14: =I14*12/365 | K14: =I14*12 | L14: _bmad-output/specs/spec-corporate-portal-poc/stack.md Private endpoints: ADLS, SQL, Key Vault and Event Hubs | M14: Azure Retail Prices API, Azure DNS / Private Zone, Zone 1, USD per 1, meterId 0b608a26-f611-4232-8192-ce81b6b57194, fetched 2026-09-30 | N14: one zone per private-endpoint service | O14: Test
A15: 11 | B15: NAT gateway (Databricks egress) | C15: NAT Gateway | D15: Standard | E15: 1 Hour | F15: 0.045 | G15: 1 | H15: =HoursPerMonth | I15: =F15*G15*H15*FxRate | J15: =I15*12/365 | K15: =I15*12 | L15: _bmad-output/specs/spec-corporate-portal-poc/stack.md VNet-injected with a NAT gateway | M15: Azure Retail Prices API, NAT Gateway / Standard Gateway, Global, USD per 1 Hour, meterId ae30040a-67f5-485b-b0f4-a6ef50504d9c, fetched 2026-09-30 | O15: Test
